Internal Server Error: /accounts/register/
Traceback (most recent call last):
  File "c:\Python27\lib\site-packages\django\core\handlers\base.py", line 103, in get_response
    resolver_match = resolver.resolve(request.path_info)
  File "c:\Python27\lib\site-packages\django\core\urlresolvers.py", line 319, in resolve
    for pattern in self.url_patterns:
  File "c:\Python27\lib\site-packages\django\core\urlresolvers.py", line 347, in url_patterns
    patterns = getattr(self.urlconf_module, "urlpatterns", self.urlconf_module)
  File "c:\Python27\lib\site-packages\django\core\urlresolvers.py", line 342, in urlconf_module
    self._urlconf_module = import_module(self.urlconf_name)
  File "c:\Python27\lib\site-packages\django\utils\importlib.py", line 35, in import_module
    __import__(name)
  File "d:\GitHub\Online-questionnaire-survey-system\qsystem\qsystem\urls.py", line 17, in <module>
    url(r'^accounts/', include('accounts.urls')),
  File "c:\Python27\lib\site-packages\django\conf\urls\__init__.py", line 25, in include
    urlconf_module = import_module(urlconf_module)
  File "c:\Python27\lib\site-packages\django\utils\importlib.py", line 35, in import_module
    __import__(name)
  File "d:\GitHub\Online-questionnaire-survey-system\qsystem\accounts\urls.py", line 2, in <module>
    from accounts import views
  File "d:\GitHub\Online-questionnaire-survey-system\qsystem\accounts\views.py", line 39
    
    ^
IndentationError: expected an indented block
Internal Server Error: /accounts/register/
Traceback (most recent call last):
  File "c:\Python27\lib\site-packages\django\core\handlers\base.py", line 103, in get_response
    resolver_match = resolver.resolve(request.path_info)
  File "c:\Python27\lib\site-packages\django\core\urlresolvers.py", line 319, in resolve
    for pattern in self.url_patterns:
  File "c:\Python27\lib\site-packages\django\core\urlresolvers.py", line 347, in url_patterns
    patterns = getattr(self.urlconf_module, "urlpatterns", self.urlconf_module)
  File "c:\Python27\lib\site-packages\django\core\urlresolvers.py", line 342, in urlconf_module
    self._urlconf_module = import_module(self.urlconf_name)
  File "c:\Python27\lib\site-packages\django\utils\importlib.py", line 35, in import_module
    __import__(name)
  File "d:\GitHub\Online-questionnaire-survey-system\qsystem\qsystem\urls.py", line 17, in <module>
    url(r'^accounts/', include('accounts.urls')),
  File "c:\Python27\lib\site-packages\django\conf\urls\__init__.py", line 25, in include
    urlconf_module = import_module(urlconf_module)
  File "c:\Python27\lib\site-packages\django\utils\importlib.py", line 35, in import_module
    __import__(name)
  File "d:\GitHub\Online-questionnaire-survey-system\qsystem\accounts\urls.py", line 2, in <module>
    from accounts import views
  File "d:\GitHub\Online-questionnaire-survey-system\qsystem\accounts\views.py", line 3, in <module>
    from accounts.models import User, UserForm
  File "d:\GitHub\Online-questionnaire-survey-system\qsystem\accounts\models.py", line 3
    <<<<<<< HEAD
     ^
SyntaxError: invalid syntax
Internal Server Error: /accounts/register/
Traceback (most recent call last):
  File "c:\Python27\lib\site-packages\django\core\handlers\base.py", line 103, in get_response
    resolver_match = resolver.resolve(request.path_info)
  File "c:\Python27\lib\site-packages\django\core\urlresolvers.py", line 319, in resolve
    for pattern in self.url_patterns:
  File "c:\Python27\lib\site-packages\django\core\urlresolvers.py", line 347, in url_patterns
    patterns = getattr(self.urlconf_module, "urlpatterns", self.urlconf_module)
  File "c:\Python27\lib\site-packages\django\core\urlresolvers.py", line 342, in urlconf_module
    self._urlconf_module = import_module(self.urlconf_name)
  File "c:\Python27\lib\site-packages\django\utils\importlib.py", line 35, in import_module
    __import__(name)
  File "d:\GitHub\Online-questionnaire-survey-system\qsystem\qsystem\urls.py", line 17, in <module>
    url(r'^accounts/', include('accounts.urls')),
  File "c:\Python27\lib\site-packages\django\conf\urls\__init__.py", line 25, in include
    urlconf_module = import_module(urlconf_module)
  File "c:\Python27\lib\site-packages\django\utils\importlib.py", line 35, in import_module
    __import__(name)
  File "d:\GitHub\Online-questionnaire-survey-system\qsystem\accounts\urls.py", line 7, in <module>
    url(r'^login/$', vies.login, name = 'login'),
NameError: name 'vies' is not defined
Internal Server Error: /accounts/register/
Traceback (most recent call last):
  File "c:\Python27\lib\site-packages\django\core\handlers\base.py", line 103, in get_response
    resolver_match = resolver.resolve(request.path_info)
  File "c:\Python27\lib\site-packages\django\core\urlresolvers.py", line 319, in resolve
    for pattern in self.url_patterns:
  File "c:\Python27\lib\site-packages\django\core\urlresolvers.py", line 347, in url_patterns
    patterns = getattr(self.urlconf_module, "urlpatterns", self.urlconf_module)
  File "c:\Python27\lib\site-packages\django\core\urlresolvers.py", line 342, in urlconf_module
    self._urlconf_module = import_module(self.urlconf_name)
  File "c:\Python27\lib\site-packages\django\utils\importlib.py", line 35, in import_module
    __import__(name)
  File "d:\GitHub\Online-questionnaire-survey-system\qsystem\qsystem\urls.py", line 17, in <module>
    url(r'^accounts/', include('accounts.urls')),
  File "c:\Python27\lib\site-packages\django\conf\urls\__init__.py", line 25, in include
    urlconf_module = import_module(urlconf_module)
  File "c:\Python27\lib\site-packages\django\utils\importlib.py", line 35, in import_module
    __import__(name)
  File "d:\GitHub\Online-questionnaire-survey-system\qsystem\accounts\urls.py", line 8, in <module>
    url(r'^login/submit/$', vies.login_submit, name = 'login'),
NameError: name 'vies' is not defined
Internal Server Error: /accounts/register/
Traceback (most recent call last):
  File "c:\Python27\lib\site-packages\django\core\handlers\base.py", line 103, in get_response
    resolver_match = resolver.resolve(request.path_info)
  File "c:\Python27\lib\site-packages\django\core\urlresolvers.py", line 319, in resolve
    for pattern in self.url_patterns:
  File "c:\Python27\lib\site-packages\django\core\urlresolvers.py", line 347, in url_patterns
    patterns = getattr(self.urlconf_module, "urlpatterns", self.urlconf_module)
  File "c:\Python27\lib\site-packages\django\core\urlresolvers.py", line 342, in urlconf_module
    self._urlconf_module = import_module(self.urlconf_name)
  File "c:\Python27\lib\site-packages\django\utils\importlib.py", line 35, in import_module
    __import__(name)
  File "d:\GitHub\Online-questionnaire-survey-system\qsystem\qsystem\urls.py", line 17, in <module>
    url(r'^accounts/', include('accounts.urls')),
  File "c:\Python27\lib\site-packages\django\conf\urls\__init__.py", line 25, in include
    urlconf_module = import_module(urlconf_module)
  File "c:\Python27\lib\site-packages\django\utils\importlib.py", line 35, in import_module
    __import__(name)
  File "d:\GitHub\Online-questionnaire-survey-system\qsystem\accounts\urls.py", line 8, in <module>
    url(r'^login/submit/$', vies.login_submit, name = 'login'),
NameError: name 'vies' is not defined
Internal Server Error: /accounts/register/
Traceback (most recent call last):
  File "c:\Python27\lib\site-packages\django\core\handlers\base.py", line 103, in get_response
    resolver_match = resolver.resolve(request.path_info)
  File "c:\Python27\lib\site-packages\django\core\urlresolvers.py", line 319, in resolve
    for pattern in self.url_patterns:
  File "c:\Python27\lib\site-packages\django\core\urlresolvers.py", line 347, in url_patterns
    patterns = getattr(self.urlconf_module, "urlpatterns", self.urlconf_module)
  File "c:\Python27\lib\site-packages\django\core\urlresolvers.py", line 342, in urlconf_module
    self._urlconf_module = import_module(self.urlconf_name)
  File "c:\Python27\lib\site-packages\django\utils\importlib.py", line 35, in import_module
    __import__(name)
  File "d:\GitHub\Online-questionnaire-survey-system\qsystem\qsystem\urls.py", line 17, in <module>
    url(r'^accounts/', include('accounts.urls')),
  File "c:\Python27\lib\site-packages\django\conf\urls\__init__.py", line 25, in include
    urlconf_module = import_module(urlconf_module)
  File "c:\Python27\lib\site-packages\django\utils\importlib.py", line 35, in import_module
    __import__(name)
  File "d:\GitHub\Online-questionnaire-survey-system\qsystem\accounts\urls.py", line 8, in <module>
    url(r'^login/submit/$', vies.login_submit, name = 'login'),
NameError: name 'vies' is not defined
Internal Server Error: /accounts/register/
Traceback (most recent call last):
  File "c:\Python27\lib\site-packages\django\core\handlers\base.py", line 115, in get_response
    response = callback(request, *callback_args, **callback_kwargs)
  File "d:\GitHub\Online-questionnaire-survey-system\qsystem\accounts\views.py", line 11, in register
    return render(request, 'accounts/register.html', {"error_msg":error_msg, "is_error":is_error})
  File "c:\Python27\lib\site-packages\django\shortcuts\__init__.py", line 53, in render
    return HttpResponse(loader.render_to_string(*args, **kwargs),
  File "c:\Python27\lib\site-packages\django\template\loader.py", line 170, in render_to_string
    t = get_template(template_name)
  File "c:\Python27\lib\site-packages\django\template\loader.py", line 146, in get_template
    template, origin = find_template(template_name)
  File "c:\Python27\lib\site-packages\django\template\loader.py", line 139, in find_template
    raise TemplateDoesNotExist(name)
TemplateDoesNotExist: accounts/register.html
Internal Server Error: /accounts/register/
Traceback (most recent call last):
  File "c:\Python27\lib\site-packages\django\core\handlers\base.py", line 115, in get_response
    response = callback(request, *callback_args, **callback_kwargs)
  File "d:\GitHub\Online-questionnaire-survey-system\qsystem\accounts\views.py", line 11, in register
    return render(request, 'accounts/register.html', {"error_msg":error_msg, "is_error":is_error})
  File "c:\Python27\lib\site-packages\django\shortcuts\__init__.py", line 53, in render
    return HttpResponse(loader.render_to_string(*args, **kwargs),
  File "c:\Python27\lib\site-packages\django\template\loader.py", line 170, in render_to_string
    t = get_template(template_name)
  File "c:\Python27\lib\site-packages\django\template\loader.py", line 146, in get_template
    template, origin = find_template(template_name)
  File "c:\Python27\lib\site-packages\django\template\loader.py", line 139, in find_template
    raise TemplateDoesNotExist(name)
TemplateDoesNotExist: accounts/register.html
Internal Server Error: /accounts/register/
Traceback (most recent call last):
  File "c:\Python27\lib\site-packages\django\core\handlers\base.py", line 115, in get_response
    response = callback(request, *callback_args, **callback_kwargs)
  File "d:\GitHub\Online-questionnaire-survey-system\qsystem\accounts\views.py", line 11, in register
    return render(request, 'accounts/register.html', {"error_msg":error_msg, "is_error":is_error})
  File "c:\Python27\lib\site-packages\django\shortcuts\__init__.py", line 53, in render
    return HttpResponse(loader.render_to_string(*args, **kwargs),
  File "c:\Python27\lib\site-packages\django\template\loader.py", line 170, in render_to_string
    t = get_template(template_name)
  File "c:\Python27\lib\site-packages\django\template\loader.py", line 146, in get_template
    template, origin = find_template(template_name)
  File "c:\Python27\lib\site-packages\django\template\loader.py", line 139, in find_template
    raise TemplateDoesNotExist(name)
TemplateDoesNotExist: accounts/register.html
Internal Server Error: /accounts/register/
Traceback (most recent call last):
  File "c:\Python27\lib\site-packages\django\core\handlers\base.py", line 115, in get_response
    response = callback(request, *callback_args, **callback_kwargs)
  File "d:\GitHub\Online-questionnaire-survey-system\qsystem\accounts\views.py", line 11, in register
    return render(request, 'accounts/register.html', {"error_msg":error_msg, "is_error":is_error})
  File "c:\Python27\lib\site-packages\django\shortcuts\__init__.py", line 53, in render
    return HttpResponse(loader.render_to_string(*args, **kwargs),
  File "c:\Python27\lib\site-packages\django\template\loader.py", line 170, in render_to_string
    t = get_template(template_name)
  File "c:\Python27\lib\site-packages\django\template\loader.py", line 146, in get_template
    template, origin = find_template(template_name)
  File "c:\Python27\lib\site-packages\django\template\loader.py", line 139, in find_template
    raise TemplateDoesNotExist(name)
TemplateDoesNotExist: accounts/register.html
Internal Server Error: /accounts/register/
Traceback (most recent call last):
  File "c:\Python27\lib\site-packages\django\core\handlers\base.py", line 115, in get_response
    response = callback(request, *callback_args, **callback_kwargs)
  File "d:\GitHub\Online-questionnaire-survey-system\qsystem\accounts\views.py", line 11, in register
    return render(request, 'accounts/register.html', {"error_msg":error_msg, "is_error":is_error})
  File "c:\Python27\lib\site-packages\django\shortcuts\__init__.py", line 53, in render
    return HttpResponse(loader.render_to_string(*args, **kwargs),
  File "c:\Python27\lib\site-packages\django\template\loader.py", line 170, in render_to_string
    t = get_template(template_name)
  File "c:\Python27\lib\site-packages\django\template\loader.py", line 146, in get_template
    template, origin = find_template(template_name)
  File "c:\Python27\lib\site-packages\django\template\loader.py", line 139, in find_template
    raise TemplateDoesNotExist(name)
TemplateDoesNotExist: accounts/register.html
Internal Server Error: /accounts/register/
Traceback (most recent call last):
  File "c:\Python27\lib\site-packages\django\core\handlers\base.py", line 115, in get_response
    response = callback(request, *callback_args, **callback_kwargs)
  File "d:\GitHub\Online-questionnaire-survey-system\qsystem\accounts\views.py", line 11, in register
    return render(request, 'accounts/register.html', {"error_msg":error_msg, "is_error":is_error})
  File "c:\Python27\lib\site-packages\django\shortcuts\__init__.py", line 53, in render
    return HttpResponse(loader.render_to_string(*args, **kwargs),
  File "c:\Python27\lib\site-packages\django\template\loader.py", line 170, in render_to_string
    t = get_template(template_name)
  File "c:\Python27\lib\site-packages\django\template\loader.py", line 146, in get_template
    template, origin = find_template(template_name)
  File "c:\Python27\lib\site-packages\django\template\loader.py", line 139, in find_template
    raise TemplateDoesNotExist(name)
TemplateDoesNotExist: accounts/register.html
Internal Server Error: /accounts/register/
Traceback (most recent call last):
  File "c:\Python27\lib\site-packages\django\core\handlers\base.py", line 115, in get_response
    response = callback(request, *callback_args, **callback_kwargs)
  File "d:\GitHub\Online-questionnaire-survey-system\qsystem\accounts\views.py", line 11, in register
    return render(request, 'accounts/register.html', {"error_msg":error_msg, "is_error":is_error})
  File "c:\Python27\lib\site-packages\django\shortcuts\__init__.py", line 53, in render
    return HttpResponse(loader.render_to_string(*args, **kwargs),
  File "c:\Python27\lib\site-packages\django\template\loader.py", line 170, in render_to_string
    t = get_template(template_name)
  File "c:\Python27\lib\site-packages\django\template\loader.py", line 146, in get_template
    template, origin = find_template(template_name)
  File "c:\Python27\lib\site-packages\django\template\loader.py", line 139, in find_template
    raise TemplateDoesNotExist(name)
TemplateDoesNotExist: accounts/register.html
Internal Server Error: /accounts/register/
Traceback (most recent call last):
  File "c:\Python27\lib\site-packages\django\core\handlers\base.py", line 115, in get_response
    response = callback(request, *callback_args, **callback_kwargs)
  File "d:\GitHub\Online-questionnaire-survey-system\qsystem\accounts\views.py", line 11, in register
    return render(request, 'accounts/register.html', {"error_msg":error_msg, "is_error":is_error})
  File "c:\Python27\lib\site-packages\django\shortcuts\__init__.py", line 53, in render
    return HttpResponse(loader.render_to_string(*args, **kwargs),
  File "c:\Python27\lib\site-packages\django\template\loader.py", line 170, in render_to_string
    t = get_template(template_name)
  File "c:\Python27\lib\site-packages\django\template\loader.py", line 146, in get_template
    template, origin = find_template(template_name)
  File "c:\Python27\lib\site-packages\django\template\loader.py", line 139, in find_template
    raise TemplateDoesNotExist(name)
TemplateDoesNotExist: accounts/register.html
Not Found: /accounts/register/submit/
Not Found: /favicon.ico
Internal Server Error: /accounts/register/
Traceback (most recent call last):
  File "c:\Python27\lib\site-packages\django\core\handlers\base.py", line 115, in get_response
    response = callback(request, *callback_args, **callback_kwargs)
  File "d:\GitHub\Online-questionnaire-survey-system\qsystem\accounts\views.py", line 11, in register
    return render(request, 'accounts/register.html', {"error_msg":error_msg, "is_error":is_error})
  File "c:\Python27\lib\site-packages\django\shortcuts\__init__.py", line 53, in render
    return HttpResponse(loader.render_to_string(*args, **kwargs),
  File "c:\Python27\lib\site-packages\django\template\loader.py", line 170, in render_to_string
    t = get_template(template_name)
  File "c:\Python27\lib\site-packages\django\template\loader.py", line 146, in get_template
    template, origin = find_template(template_name)
  File "c:\Python27\lib\site-packages\django\template\loader.py", line 139, in find_template
    raise TemplateDoesNotExist(name)
TemplateDoesNotExist: accounts/register.html
Internal Server Error: /accounts/register/
Traceback (most recent call last):
  File "c:\Python27\lib\site-packages\django\core\handlers\base.py", line 115, in get_response
    response = callback(request, *callback_args, **callback_kwargs)
  File "d:\GitHub\Online-questionnaire-survey-system\qsystem\accounts\views.py", line 11, in register
    return render(request, 'accounts/register.html', {"error_msg":error_msg, "is_error":is_error})
  File "c:\Python27\lib\site-packages\django\shortcuts\__init__.py", line 53, in render
    return HttpResponse(loader.render_to_string(*args, **kwargs),
  File "c:\Python27\lib\site-packages\django\template\loader.py", line 170, in render_to_string
    t = get_template(template_name)
  File "c:\Python27\lib\site-packages\django\template\loader.py", line 146, in get_template
    template, origin = find_template(template_name)
  File "c:\Python27\lib\site-packages\django\template\loader.py", line 139, in find_template
    raise TemplateDoesNotExist(name)
TemplateDoesNotExist: accounts/register.html
Internal Server Error: /accounts/register/
Traceback (most recent call last):
  File "c:\Python27\lib\site-packages\django\core\handlers\base.py", line 115, in get_response
    response = callback(request, *callback_args, **callback_kwargs)
  File "d:\GitHub\Online-questionnaire-survey-system\qsystem\accounts\views.py", line 11, in register
    return render(request, 'accounts/register.html', {"error_msg":error_msg, "is_error":is_error})
  File "c:\Python27\lib\site-packages\django\shortcuts\__init__.py", line 53, in render
    return HttpResponse(loader.render_to_string(*args, **kwargs),
  File "c:\Python27\lib\site-packages\django\template\loader.py", line 170, in render_to_string
    t = get_template(template_name)
  File "c:\Python27\lib\site-packages\django\template\loader.py", line 146, in get_template
    template, origin = find_template(template_name)
  File "c:\Python27\lib\site-packages\django\template\loader.py", line 135, in find_template
    source, display_name = loader(name, dirs)
  File "c:\Python27\lib\site-packages\django\template\loader.py", line 43, in __call__
    return self.load_template(template_name, template_dirs)
  File "c:\Python27\lib\site-packages\django\template\loader.py", line 49, in load_template
    template = get_template_from_string(source, origin, template_name)
  File "c:\Python27\lib\site-packages\django\template\loader.py", line 157, in get_template_from_string
    return Template(source, origin, name)
  File "c:\Python27\lib\site-packages\django\template\base.py", line 125, in __init__
    self.nodelist = compile_string(template_string, origin)
  File "c:\Python27\lib\site-packages\django\template\base.py", line 153, in compile_string
    return parser.parse()
  File "c:\Python27\lib\site-packages\django\template\base.py", line 278, in parse
    self.extend_nodelist(nodelist, compiled_result, token)
  File "c:\Python27\lib\site-packages\django\template\debug.py", line 60, in extend_nodelist
    super(DebugParser, self).extend_nodelist(nodelist, node, token)
  File "c:\Python27\lib\site-packages\django\template\base.py", line 304, in extend_nodelist
    "in the template." % node)
TemplateSyntaxError: <ExtendsNode: extends '../base.html'> must be the first tag in the template.
Internal Server Error: /accounts/register/
Traceback (most recent call last):
  File "c:\Python27\lib\site-packages\django\core\handlers\base.py", line 115, in get_response
    response = callback(request, *callback_args, **callback_kwargs)
  File "d:\GitHub\Online-questionnaire-survey-system\qsystem\accounts\views.py", line 11, in register
    return render(request, 'accounts/register.html', {"error_msg":error_msg, "is_error":is_error})
  File "c:\Python27\lib\site-packages\django\shortcuts\__init__.py", line 53, in render
    return HttpResponse(loader.render_to_string(*args, **kwargs),
  File "c:\Python27\lib\site-packages\django\template\loader.py", line 177, in render_to_string
    return t.render(context_instance)
  File "c:\Python27\lib\site-packages\django\template\base.py", line 140, in render
    return self._render(context)
  File "c:\Python27\lib\site-packages\django\template\base.py", line 134, in _render
    return self.nodelist.render(context)
  File "c:\Python27\lib\site-packages\django\template\base.py", line 830, in render
    bit = self.render_node(node, context)
  File "c:\Python27\lib\site-packages\django\template\debug.py", line 74, in render_node
    return node.render(context)
  File "c:\Python27\lib\site-packages\django\template\loader_tags.py", line 102, in render
    compiled_parent = self.get_parent(context)
  File "c:\Python27\lib\site-packages\django\template\loader_tags.py", line 99, in get_parent
    return get_template(parent)
  File "c:\Python27\lib\site-packages\django\template\loader.py", line 146, in get_template
    template, origin = find_template(template_name)
  File "c:\Python27\lib\site-packages\django\template\loader.py", line 139, in find_template
    raise TemplateDoesNotExist(name)
TemplateDoesNotExist: ../base.html
Internal Server Error: /accounts/login/
Traceback (most recent call last):
  File "c:\Python27\lib\site-packages\django\core\handlers\base.py", line 187, in get_response
    response = middleware_method(request, response)
  File "c:\Python27\lib\site-packages\django\middleware\common.py", line 106, in process_response
    if response.status_code == 404:
AttributeError: 'tuple' object has no attribute 'status_code'
Internal Server Error: /accounts/login/
Traceback (most recent call last):
  File "c:\Python27\lib\site-packages\django\core\handlers\base.py", line 115, in get_response
    response = callback(request, *callback_args, **callback_kwargs)
  File "d:\GitHub\Online-questionnaire-survey-system\qsystem\accounts\views.py", line 30, in login
    return render(request, "accounts/login.html",{"error_msg":error_msg, "is_error":is_error})
  File "c:\Python27\lib\site-packages\django\shortcuts\__init__.py", line 53, in render
    return HttpResponse(loader.render_to_string(*args, **kwargs),
  File "c:\Python27\lib\site-packages\django\template\loader.py", line 177, in render_to_string
    return t.render(context_instance)
  File "c:\Python27\lib\site-packages\django\template\base.py", line 140, in render
    return self._render(context)
  File "c:\Python27\lib\site-packages\django\template\base.py", line 134, in _render
    return self.nodelist.render(context)
  File "c:\Python27\lib\site-packages\django\template\base.py", line 830, in render
    bit = self.render_node(node, context)
  File "c:\Python27\lib\site-packages\django\template\debug.py", line 74, in render_node
    return node.render(context)
  File "c:\Python27\lib\site-packages\django\template\loader_tags.py", line 124, in render
    return compiled_parent._render(context)
  File "c:\Python27\lib\site-packages\django\template\base.py", line 134, in _render
    return self.nodelist.render(context)
  File "c:\Python27\lib\site-packages\django\template\base.py", line 830, in render
    bit = self.render_node(node, context)
  File "c:\Python27\lib\site-packages\django\template\debug.py", line 74, in render_node
    return node.render(context)
  File "c:\Python27\lib\site-packages\django\template\loader_tags.py", line 63, in render
    result = block.nodelist.render(context)
  File "c:\Python27\lib\site-packages\django\template\base.py", line 830, in render
    bit = self.render_node(node, context)
  File "c:\Python27\lib\site-packages\django\template\debug.py", line 74, in render_node
    return node.render(context)
  File "c:\Python27\lib\site-packages\django\template\defaulttags.py", line 426, in render
    raise e
NoReverseMatch: Reverse for 'login_submit' with arguments '()' and keyword arguments '{}' not found.
Internal Server Error: /accounts/login/
Traceback (most recent call last):
  File "c:\Python27\lib\site-packages\django\core\handlers\base.py", line 115, in get_response
    response = callback(request, *callback_args, **callback_kwargs)
  File "d:\GitHub\Online-questionnaire-survey-system\qsystem\accounts\views.py", line 30, in login
    return render(request, "accounts/login.html",{"error_msg":error_msg, "is_error":is_error})
  File "c:\Python27\lib\site-packages\django\shortcuts\__init__.py", line 53, in render
    return HttpResponse(loader.render_to_string(*args, **kwargs),
  File "c:\Python27\lib\site-packages\django\template\loader.py", line 177, in render_to_string
    return t.render(context_instance)
  File "c:\Python27\lib\site-packages\django\template\base.py", line 140, in render
    return self._render(context)
  File "c:\Python27\lib\site-packages\django\template\base.py", line 134, in _render
    return self.nodelist.render(context)
  File "c:\Python27\lib\site-packages\django\template\base.py", line 830, in render
    bit = self.render_node(node, context)
  File "c:\Python27\lib\site-packages\django\template\debug.py", line 74, in render_node
    return node.render(context)
  File "c:\Python27\lib\site-packages\django\template\loader_tags.py", line 124, in render
    return compiled_parent._render(context)
  File "c:\Python27\lib\site-packages\django\template\base.py", line 134, in _render
    return self.nodelist.render(context)
  File "c:\Python27\lib\site-packages\django\template\base.py", line 830, in render
    bit = self.render_node(node, context)
  File "c:\Python27\lib\site-packages\django\template\debug.py", line 74, in render_node
    return node.render(context)
  File "c:\Python27\lib\site-packages\django\template\loader_tags.py", line 63, in render
    result = block.nodelist.render(context)
  File "c:\Python27\lib\site-packages\django\template\base.py", line 830, in render
    bit = self.render_node(node, context)
  File "c:\Python27\lib\site-packages\django\template\debug.py", line 74, in render_node
    return node.render(context)
  File "c:\Python27\lib\site-packages\django\template\defaulttags.py", line 426, in render
    raise e
NoReverseMatch: Reverse for 'login_submit' with arguments '()' and keyword arguments '{}' not found.
Internal Server Error: /accounts/login/
Traceback (most recent call last):
  File "c:\Python27\lib\site-packages\django\core\handlers\base.py", line 115, in get_response
    response = callback(request, *callback_args, **callback_kwargs)
  File "d:\GitHub\Online-questionnaire-survey-system\qsystem\accounts\views.py", line 30, in login
    return render(request, "accounts/login.html",{"error_msg":error_msg, "is_error":is_error})
  File "c:\Python27\lib\site-packages\django\shortcuts\__init__.py", line 53, in render
    return HttpResponse(loader.render_to_string(*args, **kwargs),
  File "c:\Python27\lib\site-packages\django\template\loader.py", line 177, in render_to_string
    return t.render(context_instance)
  File "c:\Python27\lib\site-packages\django\template\base.py", line 140, in render
    return self._render(context)
  File "c:\Python27\lib\site-packages\django\template\base.py", line 134, in _render
    return self.nodelist.render(context)
  File "c:\Python27\lib\site-packages\django\template\base.py", line 830, in render
    bit = self.render_node(node, context)
  File "c:\Python27\lib\site-packages\django\template\debug.py", line 74, in render_node
    return node.render(context)
  File "c:\Python27\lib\site-packages\django\template\loader_tags.py", line 124, in render
    return compiled_parent._render(context)
  File "c:\Python27\lib\site-packages\django\template\base.py", line 134, in _render
    return self.nodelist.render(context)
  File "c:\Python27\lib\site-packages\django\template\base.py", line 830, in render
    bit = self.render_node(node, context)
  File "c:\Python27\lib\site-packages\django\template\debug.py", line 74, in render_node
    return node.render(context)
  File "c:\Python27\lib\site-packages\django\template\loader_tags.py", line 63, in render
    result = block.nodelist.render(context)
  File "c:\Python27\lib\site-packages\django\template\base.py", line 830, in render
    bit = self.render_node(node, context)
  File "c:\Python27\lib\site-packages\django\template\debug.py", line 74, in render_node
    return node.render(context)
  File "c:\Python27\lib\site-packages\django\template\defaulttags.py", line 426, in render
    raise e
NoReverseMatch: Reverse for 'login_submit' with arguments '()' and keyword arguments '{}' not found.
Internal Server Error: /accounts/login/submit/
Traceback (most recent call last):
  File "c:\Python27\lib\site-packages\django\core\handlers\base.py", line 115, in get_response
    response = callback(request, *callback_args, **callback_kwargs)
  File "d:\GitHub\Online-questionnaire-survey-system\qsystem\accounts\views.py", line 39, in login_submit
    response = HttpResponseRedirect('accounts/login.html')
NameError: global name 'HttpResponseRedirect' is not defined
Not Found: /accounts/login/submit/accounts/login.html
Not Found: /accounts/login/submit/accounts/login.html
Not Found: /accounts/login/submit/accounts/login.html
Internal Server Error: /accounts/login/submit/
Traceback (most recent call last):
  File "c:\Python27\lib\site-packages\django\core\handlers\base.py", line 115, in get_response
    response = callback(request, *callback_args, **callback_kwargs)
  File "d:\GitHub\Online-questionnaire-survey-system\qsystem\accounts\views.py", line 39, in login_submit
    response = HttpResponseRedirect(reverse('login', args=()))
NameError: global name 'reverse' is not defined
